<?xml version="1.0" ?>
<!-- =================================================================================== -->
<!-- |    This document was autogenerated by xacro from biped-wireframe-simplified-sat-urdf.xacro | -->
<!-- |    EDITING THIS FILE BY HAND IS NOT RECOMMENDED                                 | -->
<!-- =================================================================================== -->
<robot name="biped-wireframe-simplified-sat-urdf">
  <material name="silver">
    <color rgba="0.700 0.700 0.700 1.000"/>
  </material>
  <transmission name="Revolute 123_tran">
    <type>transmission_interface/SimpleTransmission</type>
    <joint name="Revolute 123">
      <hardwareInterface>hardware_interface/EffortJointInterface</hardwareInterface>
    </joint>
    <actuator name="Revolute 123_actr">
      <hardwareInterface>hardware_interface/EffortJointInterface</hardwareInterface>
      <mechanicalReduction>1</mechanicalReduction>
    </actuator>
  </transmission>
  <transmission name="Revolute 125_tran">
    <type>transmission_interface/SimpleTransmission</type>
    <joint name="Revolute 125">
      <hardwareInterface>hardware_interface/EffortJointInterface</hardwareInterface>
    </joint>
    <actuator name="Revolute 125_actr">
      <hardwareInterface>hardware_interface/EffortJointInterface</hardwareInterface>
      <mechanicalReduction>1</mechanicalReduction>
    </actuator>
  </transmission>
  <transmission name="Revolute 127_tran">
    <type>transmission_interface/SimpleTransmission</type>
    <joint name="Revolute 127">
      <hardwareInterface>hardware_interface/EffortJointInterface</hardwareInterface>
    </joint>
    <actuator name="Revolute 127_actr">
      <hardwareInterface>hardware_interface/EffortJointInterface</hardwareInterface>
      <mechanicalReduction>1</mechanicalReduction>
    </actuator>
  </transmission>
  <transmission name="Revolute 129_tran">
    <type>transmission_interface/SimpleTransmission</type>
    <joint name="Revolute 129">
      <hardwareInterface>hardware_interface/EffortJointInterface</hardwareInterface>
    </joint>
    <actuator name="Revolute 129_actr">
      <hardwareInterface>hardware_interface/EffortJointInterface</hardwareInterface>
      <mechanicalReduction>1</mechanicalReduction>
    </actuator>
  </transmission>
  <transmission name="Revolute 131_tran">
    <type>transmission_interface/SimpleTransmission</type>
    <joint name="Revolute 131">
      <hardwareInterface>hardware_interface/EffortJointInterface</hardwareInterface>
    </joint>
    <actuator name="Revolute 131_actr">
      <hardwareInterface>hardware_interface/EffortJointInterface</hardwareInterface>
      <mechanicalReduction>1</mechanicalReduction>
    </actuator>
  </transmission>
  <transmission name="Revolute 133_tran">
    <type>transmission_interface/SimpleTransmission</type>
    <joint name="Revolute 133">
      <hardwareInterface>hardware_interface/EffortJointInterface</hardwareInterface>
    </joint>
    <actuator name="Revolute 133_actr">
      <hardwareInterface>hardware_interface/EffortJointInterface</hardwareInterface>
      <mechanicalReduction>1</mechanicalReduction>
    </actuator>
  </transmission>
  <transmission name="Revolute 135_tran">
    <type>transmission_interface/SimpleTransmission</type>
    <joint name="Revolute 135">
      <hardwareInterface>hardware_interface/EffortJointInterface</hardwareInterface>
    </joint>
    <actuator name="Revolute 135_actr">
      <hardwareInterface>hardware_interface/EffortJointInterface</hardwareInterface>
      <mechanicalReduction>1</mechanicalReduction>
    </actuator>
  </transmission>
  <transmission name="Revolute 137_tran">
    <type>transmission_interface/SimpleTransmission</type>
    <joint name="Revolute 137">
      <hardwareInterface>hardware_interface/EffortJointInterface</hardwareInterface>
    </joint>
    <actuator name="Revolute 137_actr">
      <hardwareInterface>hardware_interface/EffortJointInterface</hardwareInterface>
      <mechanicalReduction>1</mechanicalReduction>
    </actuator>
  </transmission>
  <transmission name="Revolute 139_tran">
    <type>transmission_interface/SimpleTransmission</type>
    <joint name="Revolute 139">
      <hardwareInterface>hardware_interface/EffortJointInterface</hardwareInterface>
    </joint>
    <actuator name="Revolute 139_actr">
      <hardwareInterface>hardware_interface/EffortJointInterface</hardwareInterface>
      <mechanicalReduction>1</mechanicalReduction>
    </actuator>
  </transmission>
  <transmission name="Revolute 141_tran">
    <type>transmission_interface/SimpleTransmission</type>
    <joint name="Revolute 141">
      <hardwareInterface>hardware_interface/EffortJointInterface</hardwareInterface>
    </joint>
    <actuator name="Revolute 141_actr">
      <hardwareInterface>hardware_interface/EffortJointInterface</hardwareInterface>
      <mechanicalReduction>1</mechanicalReduction>
    </actuator>
  </transmission>
  <gazebo>
    <plugin filename="libgazebo_ros_control.so" name="control"/>
  </gazebo>
  <gazebo reference="base_link">
    <material>Gazebo/Silver</material>
    <mu1>0.2</mu1>
    <mu2>0.2</mu2>
    <selfCollide>true</selfCollide>
    <gravity>true</gravity>
  </gazebo>
  <gazebo reference="hip-roll-l_1">
    <material>Gazebo/Silver</material>
    <mu1>0.2</mu1>
    <mu2>0.2</mu2>
    <selfCollide>true</selfCollide>
  </gazebo>
  <gazebo reference="hip-link-l_1">
    <material>Gazebo/Silver</material>
    <mu1>0.2</mu1>
    <mu2>0.2</mu2>
    <selfCollide>true</selfCollide>
  </gazebo>
  <gazebo reference="hip-pitch-l_1">
    <material>Gazebo/Silver</material>
    <mu1>0.2</mu1>
    <mu2>0.2</mu2>
    <selfCollide>true</selfCollide>
  </gazebo>
  <gazebo reference="thigh-l_1">
    <material>Gazebo/Silver</material>
    <mu1>0.2</mu1>
    <mu2>0.2</mu2>
    <selfCollide>true</selfCollide>
  </gazebo>
  <gazebo reference="knee-l_1">
    <material>Gazebo/Silver</material>
    <mu1>0.2</mu1>
    <mu2>0.2</mu2>
    <selfCollide>true</selfCollide>
  </gazebo>
  <gazebo reference="tibia-l_1">
    <material>Gazebo/Silver</material>
    <mu1>0.2</mu1>
    <mu2>0.2</mu2>
    <selfCollide>true</selfCollide>
  </gazebo>
  <gazebo reference="ankle-l_1">
    <material>Gazebo/Silver</material>
    <mu1>0.2</mu1>
    <mu2>0.2</mu2>
    <selfCollide>true</selfCollide>
  </gazebo>
  <gazebo reference="tarsal-l_1">
    <material>Gazebo/Silver</material>
    <mu1>0.2</mu1>
    <mu2>0.2</mu2>
    <selfCollide>true</selfCollide>
  </gazebo>
  <gazebo reference="toes-l_1">
    <material>Gazebo/Silver</material>
    <mu1>0.2</mu1>
    <mu2>0.2</mu2>
    <selfCollide>true</selfCollide>
  </gazebo>
  <gazebo reference="foot-l_1">
    <material>Gazebo/Silver</material>
    <mu1>0.2</mu1>
    <mu2>0.2</mu2>
    <selfCollide>true</selfCollide>
  </gazebo>
  <gazebo reference="hip-roll-r_1">
    <material>Gazebo/Silver</material>
    <mu1>0.2</mu1>
    <mu2>0.2</mu2>
    <selfCollide>true</selfCollide>
  </gazebo>
  <gazebo reference="hip-link-r_1">
    <material>Gazebo/Silver</material>
    <mu1>0.2</mu1>
    <mu2>0.2</mu2>
    <selfCollide>true</selfCollide>
  </gazebo>
  <gazebo reference="hip-pitch-r_1">
    <material>Gazebo/Silver</material>
    <mu1>0.2</mu1>
    <mu2>0.2</mu2>
    <selfCollide>true</selfCollide>
  </gazebo>
  <gazebo reference="thigh-r_1">
    <material>Gazebo/Silver</material>
    <mu1>0.2</mu1>
    <mu2>0.2</mu2>
    <selfCollide>true</selfCollide>
  </gazebo>
  <gazebo reference="knee-r_1">
    <material>Gazebo/Silver</material>
    <mu1>0.2</mu1>
    <mu2>0.2</mu2>
    <selfCollide>true</selfCollide>
  </gazebo>
  <gazebo reference="tibia-r_1">
    <material>Gazebo/Silver</material>
    <mu1>0.2</mu1>
    <mu2>0.2</mu2>
    <selfCollide>true</selfCollide>
  </gazebo>
  <gazebo reference="ankle-r_1">
    <material>Gazebo/Silver</material>
    <mu1>0.2</mu1>
    <mu2>0.2</mu2>
    <selfCollide>true</selfCollide>
  </gazebo>
  <gazebo reference="tarsal-r_1">
    <material>Gazebo/Silver</material>
    <mu1>0.2</mu1>
    <mu2>0.2</mu2>
    <selfCollide>true</selfCollide>
  </gazebo>
  <gazebo reference="toes-r_1">
    <material>Gazebo/Silver</material>
    <mu1>0.2</mu1>
    <mu2>0.2</mu2>
    <selfCollide>true</selfCollide>
  </gazebo>
  <gazebo reference="foot-r_1">
    <material>Gazebo/Silver</material>
    <mu1>0.2</mu1>
    <mu2>0.2</mu2>
    <selfCollide>true</selfCollide>
  </gazebo>
  <link name="base_link">
    <inertial>
      <origin rpy="0 0 0" xyz="1.1802248376466051e-17 0.0 0.037424596835779436"/>
      <mass value="0.20421201815275936"/>
      <inertia ixx="0.000517" ixy="0.0" ixz="0.0" iyy="0.00053" iyz="0.0" izz="5.3e-05"/>
    </inertial>
    <visual>
      <origin rpy="0 0 0" xyz="0 0 0"/>
      <geometry>
        <mesh filename="../meshes/base_link.stl" scale="0.001 0.001 0.001"/>
      </geometry>
      <material name="silver"/>
    </visual>
    <collision>
      <origin rpy="0 0 0" xyz="0 0 0"/>
      <geometry>
        <mesh filename="../meshes/base_link.stl" scale="0.001 0.001 0.001"/>
      </geometry>
    </collision>
  </link>
  <link name="hip-roll-l_1">
    <inertial>
      <origin rpy="0 0 0" xyz="5.551115123125783e-17 -0.0037499999999999873 -8.326672684688674e-19"/>
      <mass value="0.4885655669211801"/>
      <inertia ixx="0.000465" ixy="0.0" ixz="-0.0" iyy="0.000739" iyz="-0.0" izz="0.000465"/>
    </inertial>
    <visual>
      <origin rpy="0 0 0" xyz="-0.08 -0.0 -0.0"/>
      <geometry>
        <mesh filename="../meshes/hip-roll-l_1.stl" scale="0.001 0.001 0.001"/>
      </geometry>
      <material name="silver"/>
    </visual>
    <collision>
      <origin rpy="0 0 0" xyz="-0.08 -0.0 -0.0"/>
      <geometry>
        <mesh filename="../meshes/hip-roll-l_1.stl" scale="0.001 0.001 0.001"/>
      </geometry>
    </collision>
  </link>
  <link name="hip-link-l_1">
    <inertial>
      <origin rpy="0 0 0" xyz="2.7755575615628914e-17 0.020319825055744634 -1.110223024625157e-18"/>
      <mass value="0.057566106473135585"/>
      <inertia ixx="2.4e-05" ixy="-0.0" ixz="-0.0" iyy="1.7e-05" iyz="-0.0" izz="2.2e-05"/>
    </inertial>
    <visual>
      <origin rpy="0 0 0" xyz="-0.08 -0.0205 0.0"/>
      <geometry>
        <mesh filename="../meshes/hip-link-l_1.stl" scale="0.001 0.001 0.001"/>
      </geometry>
      <material name="silver"/>
    </visual>
    <collision>
      <origin rpy="0 0 0" xyz="-0.08 -0.0205 0.0"/>
      <geometry>
        <mesh filename="../meshes/hip-link-l_1.stl" scale="0.001 0.001 0.001"/>
      </geometry>
    </collision>
  </link>
  <link name="hip-pitch-l_1">
    <inertial>
      <origin rpy="0 0 0" xyz="2.7755575615628914e-17 1.3877787807814457e-17 -8.396723130026427e-18"/>
      <mass value="0.33300882128051806"/>
      <inertia ixx="0.000416" ixy="-0.0" ixz="-0.0" iyy="0.000253" iyz="-0.0" izz="0.000253"/>
    </inertial>
    <visual>
      <origin rpy="0 0 0" xyz="-0.08 -0.1125 0.0"/>
      <geometry>
        <mesh filename="../meshes/hip-pitch-l_1.stl" scale="0.001 0.001 0.001"/>
      </geometry>
      <material name="silver"/>
    </visual>
    <collision>
      <origin rpy="0 0 0" xyz="-0.08 -0.1125 0.0"/>
      <geometry>
        <mesh filename="../meshes/hip-pitch-l_1.stl" scale="0.001 0.001 0.001"/>
      </geometry>
    </collision>
  </link>
  <link name="thigh-l_1">
    <inertial>
      <origin rpy="0 0 0" xyz="8.326672684688674e-17 -0.037499999999999895 -0.0649519052838326"/>
      <mass value="0.05221322554927621"/>
      <inertia ixx="3.2e-05" ixy="-0.0" ixz="-0.0" iyy="2.6e-05" iyz="-6e-06" izz="1.9e-05"/>
    </inertial>
    <visual>
      <origin rpy="0 0 0" xyz="-0.08 -0.1125 0.0"/>
      <geometry>
        <mesh filename="../meshes/thigh-l_1.stl" scale="0.001 0.001 0.001"/>
      </geometry>
      <material name="silver"/>
    </visual>
    <collision>
      <origin rpy="0 0 0" xyz="-0.08 -0.1125 0.0"/>
      <geometry>
        <mesh filename="../meshes/thigh-l_1.stl" scale="0.001 0.001 0.001"/>
      </geometry>
    </collision>
  </link>
  <link name="knee-l_1">
    <inertial>
      <origin rpy="0 0 0" xyz="1.3877787807814457e-16 2.8449465006019636e-16 1.8943233465185116e-07"/>
      <mass value="0.3330088212805181"/>
      <inertia ixx="0.000416" ixy="0.0" ixz="0.0" iyy="0.000253" iyz="-0.0" izz="0.000253"/>
    </inertial>
    <visual>
      <origin rpy="0 0 0" xyz="-0.08 -0.0375 0.129904"/>
      <geometry>
        <mesh filename="../meshes/knee-l_1.stl" scale="0.001 0.001 0.001"/>
      </geometry>
      <material name="silver"/>
    </visual>
    <collision>
      <origin rpy="0 0 0" xyz="-0.08 -0.0375 0.129904"/>
      <geometry>
        <mesh filename="../meshes/knee-l_1.stl" scale="0.001 0.001 0.001"/>
      </geometry>
    </collision>
  </link>
  <link name="tibia-l_1">
    <inertial>
      <origin rpy="0 0 0" xyz="1.8041124150158794e-16 0.06374254386577449 -0.11040513514687411"/>
      <mass value="0.057667742677937554"/>
      <inertia ixx="0.000281" ixy="0.0" ixz="0.0" iyy="0.000215" iyz="0.000118" izz="7.9e-05"/>
    </inertial>
    <visual>
      <origin rpy="0 0 0" xyz="-0.08 -0.0375 0.129904"/>
      <geometry>
        <mesh filename="../meshes/tibia-l_1.stl" scale="0.001 0.001 0.001"/>
      </geometry>
      <material name="silver"/>
    </visual>
    <collision>
      <origin rpy="0 0 0" xyz="-0.08 -0.0375 0.129904"/>
      <geometry>
        <mesh filename="../meshes/tibia-l_1.stl" scale="0.001 0.001 0.001"/>
      </geometry>
    </collision>
  </link>
  <link name="ankle-l_1">
    <inertial>
      <origin rpy="0 0 0" xyz="2.3592239273284576e-16 0.0008113134157237967 0.0007770662114900406"/>
      <mass value="0.15380067557067834"/>
      <inertia ixx="7.5e-05" ixy="0.0" ixz="-0.0" iyy="6.9e-05" iyz="-4e-06" izz="6.9e-05"/>
    </inertial>
    <visual>
      <origin rpy="0 0 0" xyz="-0.08 -0.1575 0.33775"/>
      <geometry>
        <mesh filename="../meshes/ankle-l_1.stl" scale="0.001 0.001 0.001"/>
      </geometry>
      <material name="silver"/>
    </visual>
    <collision>
      <origin rpy="0 0 0" xyz="-0.08 -0.1575 0.33775"/>
      <geometry>
        <mesh filename="../meshes/ankle-l_1.stl" scale="0.001 0.001 0.001"/>
      </geometry>
    </collision>
  </link>
  <link name="tarsal-l_1">
    <inertial>
      <origin rpy="0 0 0" xyz="2.7755575615628914e-16 -0.09671813780361416 -0.05584015037236595"/>
      <mass value="0.0775117685211312"/>
      <inertia ixx="0.000341" ixy="-0.0" ixz="0.0" iyy="9.6e-05" iyz="-0.000142" izz="0.00026"/>
    </inertial>
    <visual>
      <origin rpy="0 0 0" xyz="-0.08 -0.1575 0.33775"/>
      <geometry>
        <mesh filename="../meshes/tarsal-l_1.stl" scale="0.001 0.001 0.001"/>
      </geometry>
      <material name="silver"/>
    </visual>
    <collision>
      <origin rpy="0 0 0" xyz="-0.08 -0.1575 0.33775"/>
      <geometry>
        <mesh filename="../meshes/tarsal-l_1.stl" scale="0.001 0.001 0.001"/>
      </geometry>
    </collision>
  </link>
  <link name="toes-l_1">
    <inertial>
      <origin rpy="0 0 0" xyz="4.996003610813204e-16 4.1116742330316036e-07 9.252406962811932e-08"/>
      <mass value="0.06660176425610363"/>
      <inertia ixx="1.3e-05" ixy="0.0" ixz="0.0" iyy="2.1e-05" iyz="-0.0" izz="2.1e-05"/>
    </inertial>
    <visual>
      <origin rpy="0 0 0" xyz="-0.08 0.033026 0.44775"/>
      <geometry>
        <mesh filename="../meshes/toes-l_1.stl" scale="0.001 0.001 0.001"/>
      </geometry>
      <material name="silver"/>
    </visual>
    <collision>
      <origin rpy="0 0 0" xyz="-0.08 0.033026 0.44775"/>
      <geometry>
        <mesh filename="../meshes/toes-l_1.stl" scale="0.001 0.001 0.001"/>
      </geometry>
    </collision>
  </link>
  <link name="foot-l_1">
    <inertial>
      <origin rpy="0 0 0" xyz="7.216449660063518e-16 0.0077603101436675495 -0.028101333121559102"/>
      <mass value="0.18727145959216754"/>
      <inertia ixx="0.000281" ixy="-0.0" ixz="-0.0" iyy="8e-05" iyz="-6.7e-05" izz="0.000313"/>
    </inertial>
    <visual>
      <origin rpy="0 0 0" xyz="-0.08 0.033026 0.44775"/>
      <geometry>
        <mesh filename="../meshes/foot-l_1.stl" scale="0.001 0.001 0.001"/>
      </geometry>
      <material name="silver"/>
    </visual>
    <collision>
      <origin rpy="0 0 0" xyz="-0.08 0.033026 0.44775"/>
      <geometry>
        <mesh filename="../meshes/foot-l_1.stl" scale="0.001 0.001 0.001"/>
      </geometry>
    </collision>
  </link>
  <link name="hip-roll-r_1">
    <inertial>
      <origin rpy="0 0 0" xyz="-6.938893903907228e-17 -0.003750000000000018 9.866274346292968e-18"/>
      <mass value="0.4885655669211801"/>
      <inertia ixx="0.000465" ixy="0.0" ixz="0.0" iyy="0.000739" iyz="0.0" izz="0.000465"/>
    </inertial>
    <visual>
      <origin rpy="0 0 0" xyz="0.08 -0.008 -0.0"/>
      <geometry>
        <mesh filename="../meshes/hip-roll-r_1.stl" scale="0.001 0.001 0.001"/>
      </geometry>
      <material name="silver"/>
    </visual>
    <collision>
      <origin rpy="0 0 0" xyz="0.08 -0.008 -0.0"/>
      <geometry>
        <mesh filename="../meshes/hip-roll-r_1.stl" scale="0.001 0.001 0.001"/>
      </geometry>
    </collision>
  </link>
  <link name="hip-link-r_1">
    <inertial>
      <origin rpy="0 0 0" xyz="4.163336342344337e-17 0.0203198250557446 -3.530119281598861e-18"/>
      <mass value="0.0575661064731355"/>
      <inertia ixx="2.4e-05" ixy="-0.0" ixz="-0.0" iyy="1.7e-05" iyz="-0.0" izz="2.2e-05"/>
    </inertial>
    <visual>
      <origin rpy="0 0 0" xyz="0.08 -0.0285 -0.0"/>
      <geometry>
        <mesh filename="../meshes/hip-link-r_1.stl" scale="0.001 0.001 0.001"/>
      </geometry>
      <material name="silver"/>
    </visual>
    <collision>
      <origin rpy="0 0 0" xyz="0.08 -0.0285 -0.0"/>
      <geometry>
        <mesh filename="../meshes/hip-link-r_1.stl" scale="0.001 0.001 0.001"/>
      </geometry>
    </collision>
  </link>
  <link name="hip-pitch-r_1">
    <inertial>
      <origin rpy="0 0 0" xyz="-3.3306690738754696e-16 -8.326672684688674e-17 2.0988833737942367e-16"/>
      <mass value="0.3330088212805179"/>
      <inertia ixx="0.000416" ixy="0.0" ixz="0.0" iyy="0.000253" iyz="0.0" izz="0.000253"/>
    </inertial>
    <visual>
      <origin rpy="0 0 0" xyz="0.08 -0.1205 -0.0"/>
      <geometry>
        <mesh filename="../meshes/hip-pitch-r_1.stl" scale="0.001 0.001 0.001"/>
      </geometry>
      <material name="silver"/>
    </visual>
    <collision>
      <origin rpy="0 0 0" xyz="0.08 -0.1205 -0.0"/>
      <geometry>
        <mesh filename="../meshes/hip-pitch-r_1.stl" scale="0.001 0.001 0.001"/>
      </geometry>
    </collision>
  </link>
  <link name="thigh-r_1">
    <inertial>
      <origin rpy="0 0 0" xyz="-6.938893903907228e-17 -0.037499999999999936 -0.06495190528383282"/>
      <mass value="0.05221322554927619"/>
      <inertia ixx="3.2e-05" ixy="-0.0" ixz="-0.0" iyy="2.6e-05" iyz="-6e-06" izz="1.9e-05"/>
    </inertial>
    <visual>
      <origin rpy="0 0 0" xyz="0.08 -0.1205 -0.0"/>
      <geometry>
        <mesh filename="../meshes/thigh-r_1.stl" scale="0.001 0.001 0.001"/>
      </geometry>
      <material name="silver"/>
    </visual>
    <collision>
      <origin rpy="0 0 0" xyz="0.08 -0.1205 -0.0"/>
      <geometry>
        <mesh filename="../meshes/thigh-r_1.stl" scale="0.001 0.001 0.001"/>
      </geometry>
    </collision>
  </link>
  <link name="knee-r_1">
    <inertial>
      <origin rpy="0 0 0" xyz="9.71445146547012e-17 6.938893903907228e-17 1.8943233376367274e-07"/>
      <mass value="0.33300882128051834"/>
      <inertia ixx="0.000416" ixy="0.0" ixz="0.0" iyy="0.000253" iyz="-0.0" izz="0.000253"/>
    </inertial>
    <visual>
      <origin rpy="0 0 0" xyz="0.08 -0.0455 0.129904"/>
      <geometry>
        <mesh filename="../meshes/knee-r_1.stl" scale="0.001 0.001 0.001"/>
      </geometry>
      <material name="silver"/>
    </visual>
    <collision>
      <origin rpy="0 0 0" xyz="0.08 -0.0455 0.129904"/>
      <geometry>
        <mesh filename="../meshes/knee-r_1.stl" scale="0.001 0.001 0.001"/>
      </geometry>
    </collision>
  </link>
  <link name="tibia-r_1">
    <inertial>
      <origin rpy="0 0 0" xyz="1.3877787807814457e-16 0.06374254386577424 -0.11040513514687492"/>
      <mass value="0.05766774267793756"/>
      <inertia ixx="0.000281" ixy="-0.0" ixz="0.0" iyy="0.000215" iyz="0.000118" izz="7.9e-05"/>
    </inertial>
    <visual>
      <origin rpy="0 0 0" xyz="0.08 -0.0455 0.129904"/>
      <geometry>
        <mesh filename="../meshes/tibia-r_1.stl" scale="0.001 0.001 0.001"/>
      </geometry>
      <material name="silver"/>
    </visual>
    <collision>
      <origin rpy="0 0 0" xyz="0.08 -0.0455 0.129904"/>
      <geometry>
        <mesh filename="../meshes/tibia-r_1.stl" scale="0.001 0.001 0.001"/>
      </geometry>
    </collision>
  </link>
  <link name="ankle-r_1">
    <inertial>
      <origin rpy="0 0 0" xyz="1.124100812432971e-15 0.0008113134157236301 0.0007770662114892635"/>
      <mass value="0.15380067557067836"/>
      <inertia ixx="7.5e-05" ixy="0.0" ixz="-0.0" iyy="6.9e-05" iyz="-4e-06" izz="6.9e-05"/>
    </inertial>
    <visual>
      <origin rpy="0 0 0" xyz="0.08 -0.1655 0.33775"/>
      <geometry>
        <mesh filename="../meshes/ankle-r_1.stl" scale="0.001 0.001 0.001"/>
      </geometry>
      <material name="silver"/>
    </visual>
    <collision>
      <origin rpy="0 0 0" xyz="0.08 -0.1655 0.33775"/>
      <geometry>
        <mesh filename="../meshes/ankle-r_1.stl" scale="0.001 0.001 0.001"/>
      </geometry>
    </collision>
  </link>
  <link name="tarsal-r_1">
    <inertial>
      <origin rpy="0 0 0" xyz="4.0245584642661925e-16 -0.09671813780361424 -0.05584015037236717"/>
      <mass value="0.07751176852113106"/>
      <inertia ixx="0.000341" ixy="-0.0" ixz="0.0" iyy="9.6e-05" iyz="-0.000142" izz="0.00026"/>
    </inertial>
    <visual>
      <origin rpy="0 0 0" xyz="0.08 -0.1655 0.33775"/>
      <geometry>
        <mesh filename="../meshes/tarsal-r_1.stl" scale="0.001 0.001 0.001"/>
      </geometry>
      <material name="silver"/>
    </visual>
    <collision>
      <origin rpy="0 0 0" xyz="0.08 -0.1655 0.33775"/>
      <geometry>
        <mesh filename="../meshes/tarsal-r_1.stl" scale="0.001 0.001 0.001"/>
      </geometry>
    </collision>
  </link>
  <link name="toes-r_1">
    <inertial>
      <origin rpy="0 0 0" xyz="2.0816681711721685e-16 4.111674232233631e-07 9.252406890647435e-08"/>
      <mass value="0.06660176425610362"/>
      <inertia ixx="1.3e-05" ixy="0.0" ixz="-0.0" iyy="2.1e-05" iyz="-0.0" izz="2.1e-05"/>
    </inertial>
    <visual>
      <origin rpy="0 0 0" xyz="0.08 0.025026 0.44775"/>
      <geometry>
        <mesh filename="../meshes/toes-r_1.stl" scale="0.001 0.001 0.001"/>
      </geometry>
      <material name="silver"/>
    </visual>
    <collision>
      <origin rpy="0 0 0" xyz="0.08 0.025026 0.44775"/>
      <geometry>
        <mesh filename="../meshes/toes-r_1.stl" scale="0.001 0.001 0.001"/>
      </geometry>
    </collision>
  </link>
  <link name="foot-r_1">
    <inertial>
      <origin rpy="0 0 0" xyz="-2.636779683484747e-16 0.007760310143667563 -0.02810133312156149"/>
      <mass value="0.1872714595921685"/>
      <inertia ixx="0.000281" ixy="0.0" ixz="0.0" iyy="8e-05" iyz="-6.7e-05" izz="0.000313"/>
    </inertial>
    <visual>
      <origin rpy="0 0 0" xyz="0.08 0.025026 0.44775"/>
      <geometry>
        <mesh filename="../meshes/foot-r_1.stl" scale="0.001 0.001 0.001"/>
      </geometry>
      <material name="silver"/>
    </visual>
    <collision>
      <origin rpy="0 0 0" xyz="0.08 0.025026 0.44775"/>
      <geometry>
        <mesh filename="../meshes/foot-r_1.stl" scale="0.001 0.001 0.001"/>
      </geometry>
    </collision>
  </link>
  <joint name="fixed_hip_roll_l" type="fixed">
    <origin rpy="0 0 0" xyz="0.08 0.0 0.0"/>
    <parent link="base_link"/>
    <child link="hip-roll-l_1"/>
  </joint>
  <joint name="hip_roll_l" type="continuous">
    <origin rpy="0 0 0" xyz="0.0 0.0205 -0.0"/>
    <parent link="hip-roll-l_1"/>
    <child link="hip-link-l_1"/>
    <axis xyz="0.0 1.0 -0.0"/>
  </joint>
  <joint name="fixed_hip_pitch_l" type="fixed">
    <origin rpy="0 0 0" xyz="0.0 0.092 0.0"/>
    <parent link="hip-link-l_1"/>
    <child link="hip-pitch-l_1"/>
  </joint>
  <joint name="hip_pitch_l" type="continuous">
    <origin rpy="0 0 0" xyz="0.0 0.0 0.0"/>
    <parent link="hip-pitch-l_1"/>
    <child link="thigh-l_1"/>
    <axis xyz="-1.0 0.0 0.0"/>
  </joint>
  <joint name="fixed_knee_l" type="fixed">
    <origin rpy="0 0 0" xyz="0.0 -0.075 -0.129904"/>
    <parent link="thigh-l_1"/>
    <child link="knee-l_1"/>
  </joint>
  <joint name="knee_l" type="continuous">
    <origin rpy="0 0 0" xyz="0.0 0.0 0.0"/>
    <parent link="knee-l_1"/>
    <child link="tibia-l_1"/>
    <axis xyz="-1.0 -0.0 -0.0"/>
  </joint>
  <joint name="fixed_ankle_l" type="fixed">
    <origin rpy="0 0 0" xyz="0.0 0.12 -0.207846"/>
    <parent link="tibia-l_1"/>
    <child link="ankle-l_1"/>
  </joint>
  <joint name="ankle_l" type="continuous">
    <origin rpy="0 0 0" xyz="0.0 0.0 0.0"/>
    <parent link="ankle-l_1"/>
    <child link="tarsal-l_1"/>
    <axis xyz="1.0 0.0 0.0"/>
  </joint>
  <joint name="fixed_toe_l" type="fixed">
    <origin rpy="0 0 0" xyz="0.0 -0.190526 -0.11"/>
    <parent link="tarsal-l_1"/>
    <child link="toes-l_1"/>
  </joint>
  <joint name="feet_l" type="continuous">
    <origin rpy="0 0 0" xyz="0.0 0.0 0.0"/>
    <parent link="toes-l_1"/>
    <child link="foot-l_1"/>
    <axis xyz="-1.0 0.0 0.0"/>
  </joint>
  <joint name="fixed_hip_roll_r" type="fixed">
    <origin rpy="0 0 0" xyz="-0.08 0.008 0.0"/>
    <parent link="base_link"/>
    <child link="hip-roll-r_1"/>
  </joint>
  <joint name="hip_roll_r" type="continuous">
    <origin rpy="0 0 0" xyz="0.0 0.0205 0.0"/>
    <parent link="hip-roll-r_1"/>
    <child link="hip-link-r_1"/>
    <axis xyz="0.0 1.0 -0.0"/>
  </joint>
  <joint name="fixed_hip_pitch_r" type="fixed">
    <origin rpy="0 0 0" xyz="0.0 0.092 0.0"/>
    <parent link="hip-link-r_1"/>
    <child link="hip-pitch-r_1"/>
  </joint>
  <joint name="hip_pitch_r" type="continuous">
    <origin rpy="0 0 0" xyz="0.0 0.0 0.0"/>
    <parent link="hip-pitch-r_1"/>
    <child link="thigh-r_1"/>
    <axis xyz="-1.0 -0.0 0.0"/>
  </joint>
  <joint name="fixed_knee_r" type="fixed">
    <origin rpy="0 0 0" xyz="0.0 -0.075 -0.129904"/>
    <parent link="thigh-r_1"/>
    <child link="knee-r_1"/>
  </joint>
  <joint name="knee_r" type="continuous">
    <origin rpy="0 0 0" xyz="0.0 0.0 0.0"/>
    <parent link="knee-r_1"/>
    <child link="tibia-r_1"/>
    <axis xyz="-1.0 0.0 -0.0"/>
  </joint>
  <joint name="fixed_ankle_r" type="fixed">
    <origin rpy="0 0 0" xyz="0.0 0.12 -0.207846"/>
    <parent link="tibia-r_1"/>
    <child link="ankle-r_1"/>
  </joint>
  <joint name="ankle_r" type="continuous">
    <origin rpy="0 0 0" xyz="0.0 0.0 0.0"/>
    <parent link="ankle-r_1"/>
    <child link="tarsal-r_1"/>
    <axis xyz="1.0 -0.0 0.0"/>
  </joint>
  <joint name="fixed_toe_r" type="fixed">
    <origin rpy="0 0 0" xyz="0.0 -0.190526 -0.11"/>
    <parent link="tarsal-r_1"/>
    <child link="toes-r_1"/>
  </joint>
  <joint name="feet_r" type="continuous">
    <origin rpy="0 0 0" xyz="0.0 0.0 0.0"/>
    <parent link="toes-r_1"/>
    <child link="foot-r_1"/>
    <axis xyz="-1.0 -0.0 -0.0"/>
  </joint>
</robot>
